[2025-03-25T23:57:04.824+0000] {taskinstance.py:1956} INFO - Dependencies all met for dep_context=non-requeueable deps ti=<TaskInstance: titanic_survival_classifier.prepare_data_task manual__2025-03-25T23:56:58.231639+00:00 [queued]>
[2025-03-25T23:57:04.838+0000] {taskinstance.py:1956} INFO - Dependencies all met for dep_context=requeueable deps ti=<TaskInstance: titanic_survival_classifier.prepare_data_task manual__2025-03-25T23:56:58.231639+00:00 [queued]>
[2025-03-25T23:57:04.840+0000] {taskinstance.py:2170} INFO - Starting attempt 1 of 2
[2025-03-25T23:57:04.870+0000] {taskinstance.py:2191} INFO - Executing <Task(PythonOperator): prepare_data_task> on 2025-03-25 23:56:58.231639+00:00
[2025-03-25T23:57:04.896+0000] {standard_task_runner.py:87} INFO - Running: ['***', 'tasks', 'run', 'titanic_survival_classifier', 'prepare_data_task', 'manual__2025-03-25T23:56:58.231639+00:00', '--job-id', '2', '--raw', '--subdir', 'DAGS_FOLDER/pipeline.py', '--cfg-path', '/tmp/tmptkzl648b']
[2025-03-25T23:57:04.891+0000] {standard_task_runner.py:60} INFO - Started process 137 to run task
[2025-03-25T23:57:04.899+0000] {standard_task_runner.py:88} INFO - Job 2: Subtask prepare_data_task
[2025-03-25T23:57:04.958+0000] {warnings.py:109} WARNING - /home/***/.local/lib/python3.8/site-packages/***/settings.py:194: DeprecationWarning: The sql_alchemy_conn option in [core] has been moved to the sql_alchemy_conn option in [database] - the old setting has been used, but please update your config.
  SQL_ALCHEMY_CONN = conf.get("database", "SQL_ALCHEMY_CONN")

[2025-03-25T23:57:05.028+0000] {task_command.py:423} INFO - Running <TaskInstance: titanic_survival_classifier.prepare_data_task manual__2025-03-25T23:56:58.231639+00:00 [running]> on host 2103b6a57441
[2025-03-25T23:57:05.173+0000] {taskinstance.py:2480} INFO - Exporting env vars: AIRFLOW_CTX_DAG_OWNER='***' AIRFLOW_CTX_DAG_ID='titanic_survival_classifier' AIRFLOW_CTX_TASK_ID='prepare_data_task' AIRFLOW_CTX_EXECUTION_DATE='2025-03-25T23:56:58.231639+00:00' AIRFLOW_CTX_TRY_NUMBER='1' AIRFLOW_CTX_DAG_RUN_ID='manual__2025-03-25T23:56:58.231639+00:00'
[2025-03-25T23:57:05.176+0000] {logging_mixin.py:188} INFO - ---Preparing train data---
[2025-03-25T23:57:05.180+0000] {taskinstance.py:2698} ERROR - Task failed with exception
Traceback (most recent call last):
  File "/home/airflow/.local/lib/python3.8/site-packages/airflow/models/taskinstance.py", line 433, in _execute_task
    result = execute_callable(context=context, **execute_callable_kwargs)
  File "/home/airflow/.local/lib/python3.8/site-packages/airflow/operators/python.py", line 199, in execute
    return_value = self.execute_callable()
  File "/home/airflow/.local/lib/python3.8/site-packages/airflow/operators/python.py", line 216, in execute_callable
    return self.python_callable(*self.op_args, **self.op_kwargs)
  File "/opt/airflow/dags/pipeline.py", line 24, in prepare_data_task
    prepare_data(train_path, 'train')
  File "/opt/airflow/dags/func/ml_pipeline.py", line 20, in prepare_data
    df = pd.read_csv(file_path)
  File "/home/airflow/.local/lib/python3.8/site-packages/pandas/io/parsers/readers.py", line 912, in read_csv
    return _read(filepath_or_buffer, kwds)
  File "/home/airflow/.local/lib/python3.8/site-packages/pandas/io/parsers/readers.py", line 577, in _read
    parser = TextFileReader(filepath_or_buffer, **kwds)
  File "/home/airflow/.local/lib/python3.8/site-packages/pandas/io/parsers/readers.py", line 1407, in __init__
    self._engine = self._make_engine(f, self.engine)
  File "/home/airflow/.local/lib/python3.8/site-packages/pandas/io/parsers/readers.py", line 1661, in _make_engine
    self.handles = get_handle(
  File "/home/airflow/.local/lib/python3.8/site-packages/pandas/io/common.py", line 859, in get_handle
    handle = open(
FileNotFoundError: [Errno 2] No such file or directory: '/opt/airflow/data/titanic/train/train.csv'
[2025-03-25T23:57:05.204+0000] {taskinstance.py:1138} INFO - Marking task as UP_FOR_RETRY. dag_id=titanic_survival_classifier, task_id=prepare_data_task, execution_date=20250325T235658, start_date=20250325T235704, end_date=20250325T235705
[2025-03-25T23:57:05.229+0000] {standard_task_runner.py:107} ERROR - Failed to execute job 2 for task prepare_data_task ([Errno 2] No such file or directory: '/opt/airflow/data/titanic/train/train.csv'; 137)
[2025-03-25T23:57:05.279+0000] {local_task_job_runner.py:234} INFO - Task exited with return code 1
[2025-03-25T23:57:05.327+0000] {taskinstance.py:3280} INFO - 0 downstream tasks scheduled from follow-on schedule check
