[2025-03-25T23:59:56.878+0000] {scheduler_job_runner.py:781} ERROR - Executor reports task instance <TaskInstance: titanic_survival_classifier.prepare_data_task manual__2025-03-25T23:56:58.231639+00:00 [queued]> finished (failed) although the task says it's queued. (Info: None) Was the task killed externally?
