[2025-03-25T23:52:03.918+0000] {taskinstance.py:1956} INFO - Dependencies all met for dep_context=non-requeueable deps ti=<TaskInstance: titanic_survival_classifier.prepare_data_task manual__2025-03-25T23:46:54.072736+00:00 [queued]>
[2025-03-25T23:52:03.932+0000] {taskinstance.py:1956} INFO - Dependencies all met for dep_context=requeueable deps ti=<TaskInstance: titanic_survival_classifier.prepare_data_task manual__2025-03-25T23:46:54.072736+00:00 [queued]>
[2025-03-25T23:52:03.933+0000] {taskinstance.py:2170} INFO - Starting attempt 2 of 2
[2025-03-25T23:52:03.961+0000] {taskinstance.py:2191} INFO - Executing <Task(PythonOperator): prepare_data_task> on 2025-03-25 23:46:54.072736+00:00
[2025-03-25T23:52:03.972+0000] {standard_task_runner.py:60} INFO - Started process 309 to run task
[2025-03-25T23:52:03.978+0000] {standard_task_runner.py:87} INFO - Running: ['***', 'tasks', 'run', 'titanic_survival_classifier', 'prepare_data_task', 'manual__2025-03-25T23:46:54.072736+00:00', '--job-id', '3', '--raw', '--subdir', 'DAGS_FOLDER/pipeline.py', '--cfg-path', '/tmp/tmp81dynn6j']
[2025-03-25T23:52:03.979+0000] {standard_task_runner.py:88} INFO - Job 3: Subtask prepare_data_task
[2025-03-25T23:52:04.001+0000] {warnings.py:109} WARNING - /home/***/.local/lib/python3.8/site-packages/***/settings.py:194: DeprecationWarning: The sql_alchemy_conn option in [core] has been moved to the sql_alchemy_conn option in [database] - the old setting has been used, but please update your config.
  SQL_ALCHEMY_CONN = conf.get("database", "SQL_ALCHEMY_CONN")

[2025-03-25T23:52:04.058+0000] {task_command.py:423} INFO - Running <TaskInstance: titanic_survival_classifier.prepare_data_task manual__2025-03-25T23:46:54.072736+00:00 [running]> on host 2bb884c69b67
[2025-03-25T23:52:04.180+0000] {taskinstance.py:2480} INFO - Exporting env vars: AIRFLOW_CTX_DAG_OWNER='***' AIRFLOW_CTX_DAG_ID='titanic_survival_classifier' AIRFLOW_CTX_TASK_ID='prepare_data_task' AIRFLOW_CTX_EXECUTION_DATE='2025-03-25T23:46:54.072736+00:00' AIRFLOW_CTX_TRY_NUMBER='2' AIRFLOW_CTX_DAG_RUN_ID='manual__2025-03-25T23:46:54.072736+00:00'
[2025-03-25T23:52:04.183+0000] {logging_mixin.py:188} INFO - ---Preparing train data---
[2025-03-25T23:52:04.187+0000] {taskinstance.py:2698} ERROR - Task failed with exception
Traceback (most recent call last):
  File "/home/airflow/.local/lib/python3.8/site-packages/airflow/models/taskinstance.py", line 433, in _execute_task
    result = execute_callable(context=context, **execute_callable_kwargs)
  File "/home/airflow/.local/lib/python3.8/site-packages/airflow/operators/python.py", line 199, in execute
    return_value = self.execute_callable()
  File "/home/airflow/.local/lib/python3.8/site-packages/airflow/operators/python.py", line 216, in execute_callable
    return self.python_callable(*self.op_args, **self.op_kwargs)
  File "/opt/airflow/dags/pipeline.py", line 24, in prepare_data_task
    prepare_data(train_path, 'train')
  File "/opt/airflow/dags/func/ml_pipeline.py", line 20, in prepare_data
    df = pd.read_csv(file_path)
  File "/home/airflow/.local/lib/python3.8/site-packages/pandas/io/parsers/readers.py", line 912, in read_csv
    return _read(filepath_or_buffer, kwds)
  File "/home/airflow/.local/lib/python3.8/site-packages/pandas/io/parsers/readers.py", line 577, in _read
    parser = TextFileReader(filepath_or_buffer, **kwds)
  File "/home/airflow/.local/lib/python3.8/site-packages/pandas/io/parsers/readers.py", line 1407, in __init__
    self._engine = self._make_engine(f, self.engine)
  File "/home/airflow/.local/lib/python3.8/site-packages/pandas/io/parsers/readers.py", line 1661, in _make_engine
    self.handles = get_handle(
  File "/home/airflow/.local/lib/python3.8/site-packages/pandas/io/common.py", line 859, in get_handle
    handle = open(
FileNotFoundError: [Errno 2] No such file or directory: '/opt/airflow/data/titanic/train/train.csv'
[2025-03-25T23:52:04.215+0000] {taskinstance.py:1138} INFO - Marking task as FAILED. dag_id=titanic_survival_classifier, task_id=prepare_data_task, execution_date=20250325T234654, start_date=20250325T235203, end_date=20250325T235204
[2025-03-25T23:52:04.242+0000] {standard_task_runner.py:107} ERROR - Failed to execute job 3 for task prepare_data_task ([Errno 2] No such file or directory: '/opt/airflow/data/titanic/train/train.csv'; 309)
[2025-03-25T23:52:04.273+0000] {local_task_job_runner.py:234} INFO - Task exited with return code 1
[2025-03-25T23:52:04.321+0000] {taskinstance.py:3280} INFO - 0 downstream tasks scheduled from follow-on schedule check
