[2025-03-26T00:42:47.627+0000] {taskinstance.py:1956} INFO - Dependencies all met for dep_context=non-requeueable deps ti=<TaskInstance: titanic_survival_classifier.prepare_data_task manual__2025-03-26T00:42:43.687439+00:00 [queued]>
[2025-03-26T00:42:47.646+0000] {taskinstance.py:1956} INFO - Dependencies all met for dep_context=requeueable deps ti=<TaskInstance: titanic_survival_classifier.prepare_data_task manual__2025-03-26T00:42:43.687439+00:00 [queued]>
[2025-03-26T00:42:47.647+0000] {taskinstance.py:2170} INFO - Starting attempt 1 of 2
[2025-03-26T00:42:47.674+0000] {taskinstance.py:2191} INFO - Executing <Task(PythonOperator): prepare_data_task> on 2025-03-26 00:42:43.687439+00:00
[2025-03-26T00:42:47.687+0000] {standard_task_runner.py:60} INFO - Started process 1415 to run task
[2025-03-26T00:42:47.691+0000] {standard_task_runner.py:87} INFO - Running: ['***', 'tasks', 'run', 'titanic_survival_classifier', 'prepare_data_task', 'manual__2025-03-26T00:42:43.687439+00:00', '--job-id', '12', '--raw', '--subdir', 'DAGS_FOLDER/pipeline.py', '--cfg-path', '/tmp/tmpucmwh_7z']
[2025-03-26T00:42:47.694+0000] {standard_task_runner.py:88} INFO - Job 12: Subtask prepare_data_task
[2025-03-26T00:42:47.717+0000] {warnings.py:109} WARNING - /home/***/.local/lib/python3.8/site-packages/***/settings.py:194: DeprecationWarning: The sql_alchemy_conn option in [core] has been moved to the sql_alchemy_conn option in [database] - the old setting has been used, but please update your config.
  SQL_ALCHEMY_CONN = conf.get("database", "SQL_ALCHEMY_CONN")

[2025-03-26T00:42:47.780+0000] {task_command.py:423} INFO - Running <TaskInstance: titanic_survival_classifier.prepare_data_task manual__2025-03-26T00:42:43.687439+00:00 [running]> on host 0f3b2e2ddf0a
[2025-03-26T00:42:47.990+0000] {taskinstance.py:2480} INFO - Exporting env vars: AIRFLOW_CTX_DAG_OWNER='***' AIRFLOW_CTX_DAG_ID='titanic_survival_classifier' AIRFLOW_CTX_TASK_ID='prepare_data_task' AIRFLOW_CTX_EXECUTION_DATE='2025-03-26T00:42:43.687439+00:00' AIRFLOW_CTX_TRY_NUMBER='1' AIRFLOW_CTX_DAG_RUN_ID='manual__2025-03-26T00:42:43.687439+00:00'
[2025-03-26T00:42:47.993+0000] {logging_mixin.py:188} INFO - ---Preparing train data---
[2025-03-26T00:42:48.011+0000] {taskinstance.py:2698} ERROR - Task failed with exception
Traceback (most recent call last):
  File "/home/airflow/.local/lib/python3.8/site-packages/airflow/models/taskinstance.py", line 433, in _execute_task
    result = execute_callable(context=context, **execute_callable_kwargs)
  File "/home/airflow/.local/lib/python3.8/site-packages/airflow/operators/python.py", line 199, in execute
    return_value = self.execute_callable()
  File "/home/airflow/.local/lib/python3.8/site-packages/airflow/operators/python.py", line 216, in execute_callable
    return self.python_callable(*self.op_args, **self.op_kwargs)
  File "/opt/airflow/dags/pipeline.py", line 24, in prepare_data_task
    prepare_data(train_path, 'train')
  File "/opt/airflow/dags/func/ml_pipeline.py", line 23, in prepare_data
    from dags.func import data_validator
ModuleNotFoundError: No module named 'dags'
[2025-03-26T00:42:48.034+0000] {taskinstance.py:1138} INFO - Marking task as UP_FOR_RETRY. dag_id=titanic_survival_classifier, task_id=prepare_data_task, execution_date=20250326T004243, start_date=20250326T004247, end_date=20250326T004248
[2025-03-26T00:42:48.059+0000] {standard_task_runner.py:107} ERROR - Failed to execute job 12 for task prepare_data_task (No module named 'dags'; 1415)
[2025-03-26T00:42:48.106+0000] {local_task_job_runner.py:234} INFO - Task exited with return code 1
[2025-03-26T00:42:48.153+0000] {taskinstance.py:3280} INFO - 0 downstream tasks scheduled from follow-on schedule check
