[2025-03-26T00:47:35.714+0000] {taskinstance.py:1956} INFO - Dependencies all met for dep_context=non-requeueable deps ti=<TaskInstance: titanic_survival_classifier.model_validation_task manual__2025-03-26T00:26:14.173301+00:00 [queued]>
[2025-03-26T00:47:35.734+0000] {taskinstance.py:1956} INFO - Dependencies all met for dep_context=requeueable deps ti=<TaskInstance: titanic_survival_classifier.model_validation_task manual__2025-03-26T00:26:14.173301+00:00 [queued]>
[2025-03-26T00:47:35.735+0000] {taskinstance.py:2170} INFO - Starting attempt 2 of 3
[2025-03-26T00:47:35.771+0000] {taskinstance.py:2191} INFO - Executing <Task(PythonOperator): model_validation_task> on 2025-03-26 00:26:14.173301+00:00
[2025-03-26T00:47:35.783+0000] {standard_task_runner.py:60} INFO - Started process 1594 to run task
[2025-03-26T00:47:35.788+0000] {standard_task_runner.py:87} INFO - Running: ['***', 'tasks', 'run', 'titanic_survival_classifier', 'model_validation_task', 'manual__2025-03-26T00:26:14.173301+00:00', '--job-id', '13', '--raw', '--subdir', 'DAGS_FOLDER/pipeline.py', '--cfg-path', '/tmp/tmpeybt1ep2']
[2025-03-26T00:47:35.791+0000] {standard_task_runner.py:88} INFO - Job 13: Subtask model_validation_task
[2025-03-26T00:47:35.817+0000] {warnings.py:109} WARNING - /home/***/.local/lib/python3.8/site-packages/***/settings.py:194: DeprecationWarning: The sql_alchemy_conn option in [core] has been moved to the sql_alchemy_conn option in [database] - the old setting has been used, but please update your config.
  SQL_ALCHEMY_CONN = conf.get("database", "SQL_ALCHEMY_CONN")

[2025-03-26T00:47:35.882+0000] {task_command.py:423} INFO - Running <TaskInstance: titanic_survival_classifier.model_validation_task manual__2025-03-26T00:26:14.173301+00:00 [running]> on host 0f3b2e2ddf0a
[2025-03-26T00:47:36.018+0000] {taskinstance.py:2480} INFO - Exporting env vars: AIRFLOW_CTX_DAG_OWNER='***' AIRFLOW_CTX_DAG_ID='titanic_survival_classifier' AIRFLOW_CTX_TASK_ID='model_validation_task' AIRFLOW_CTX_EXECUTION_DATE='2025-03-26T00:26:14.173301+00:00' AIRFLOW_CTX_TRY_NUMBER='2' AIRFLOW_CTX_DAG_RUN_ID='manual__2025-03-26T00:26:14.173301+00:00'
[2025-03-26T00:47:36.048+0000] {logging_mixin.py:188} INFO - ---Testing Model---
[2025-03-26T00:47:36.066+0000] {logging_mixin.py:188} INFO - Test predictions complete
[2025-03-26T00:47:36.068+0000] {taskinstance.py:2698} ERROR - Task failed with exception
Traceback (most recent call last):
  File "/home/airflow/.local/lib/python3.8/site-packages/airflow/models/taskinstance.py", line 433, in _execute_task
    result = execute_callable(context=context, **execute_callable_kwargs)
  File "/home/airflow/.local/lib/python3.8/site-packages/airflow/operators/python.py", line 199, in execute
    return_value = self.execute_callable()
  File "/home/airflow/.local/lib/python3.8/site-packages/airflow/operators/python.py", line 216, in execute_callable
    return self.python_callable(*self.op_args, **self.op_kwargs)
  File "/opt/airflow/dags/pipeline.py", line 65, in model_validation_task
    if isinstance(result[1], pd.DataFrame):  # Unlabeled data
NameError: name 'pd' is not defined
[2025-03-26T00:47:36.085+0000] {taskinstance.py:1138} INFO - Marking task as UP_FOR_RETRY. dag_id=titanic_survival_classifier, task_id=model_validation_task, execution_date=20250326T002614, start_date=20250326T004735, end_date=20250326T004736
[2025-03-26T00:47:36.110+0000] {standard_task_runner.py:107} ERROR - Failed to execute job 13 for task model_validation_task (name 'pd' is not defined; 1594)
[2025-03-26T00:47:36.163+0000] {local_task_job_runner.py:234} INFO - Task exited with return code 1
[2025-03-26T00:47:36.196+0000] {taskinstance.py:3280} INFO - 0 downstream tasks scheduled from follow-on schedule check
