[2025-03-26T01:00:44.557+0000] {taskinstance.py:1956} INFO - Dependencies all met for dep_context=non-requeueable deps ti=<TaskInstance: titanic_survival_classifier.prepare_data_task manual__2025-03-26T01:00:39.970917+00:00 [queued]>
[2025-03-26T01:00:44.579+0000] {taskinstance.py:1956} INFO - Dependencies all met for dep_context=requeueable deps ti=<TaskInstance: titanic_survival_classifier.prepare_data_task manual__2025-03-26T01:00:39.970917+00:00 [queued]>
[2025-03-26T01:00:44.580+0000] {taskinstance.py:2170} INFO - Starting attempt 1 of 2
[2025-03-26T01:00:44.609+0000] {taskinstance.py:2191} INFO - Executing <Task(PythonOperator): prepare_data_task> on 2025-03-26 01:00:39.970917+00:00
[2025-03-26T01:00:44.623+0000] {standard_task_runner.py:60} INFO - Started process 2159 to run task
[2025-03-26T01:00:44.628+0000] {standard_task_runner.py:87} INFO - Running: ['***', 'tasks', 'run', 'titanic_survival_classifier', 'prepare_data_task', 'manual__2025-03-26T01:00:39.970917+00:00', '--job-id', '23', '--raw', '--subdir', 'DAGS_FOLDER/pipeline.py', '--cfg-path', '/tmp/tmp1zv7lzkh']
[2025-03-26T01:00:44.630+0000] {standard_task_runner.py:88} INFO - Job 23: Subtask prepare_data_task
[2025-03-26T01:00:44.657+0000] {warnings.py:109} WARNING - /home/***/.local/lib/python3.8/site-packages/***/settings.py:194: DeprecationWarning: The sql_alchemy_conn option in [core] has been moved to the sql_alchemy_conn option in [database] - the old setting has been used, but please update your config.
  SQL_ALCHEMY_CONN = conf.get("database", "SQL_ALCHEMY_CONN")

[2025-03-26T01:00:44.726+0000] {task_command.py:423} INFO - Running <TaskInstance: titanic_survival_classifier.prepare_data_task manual__2025-03-26T01:00:39.970917+00:00 [running]> on host 0f3b2e2ddf0a
[2025-03-26T01:00:44.883+0000] {taskinstance.py:2480} INFO - Exporting env vars: AIRFLOW_CTX_DAG_OWNER='***' AIRFLOW_CTX_DAG_ID='titanic_survival_classifier' AIRFLOW_CTX_TASK_ID='prepare_data_task' AIRFLOW_CTX_EXECUTION_DATE='2025-03-26T01:00:39.970917+00:00' AIRFLOW_CTX_TRY_NUMBER='1' AIRFLOW_CTX_DAG_RUN_ID='manual__2025-03-26T01:00:39.970917+00:00'
[2025-03-26T01:00:44.887+0000] {logging_mixin.py:188} INFO - ---Preparing train data---
[2025-03-26T01:00:44.946+0000] {logging_mixin.py:188} INFO - {'Schema Validation': 'No Issue with Schema', 'Missing Values': {'Age': '19.87%', 'Cabin': '77.10%', 'Embarked': '0.22%'}, 'Duplicate Rows': 0, 'Duplicate IDs': 0}
[2025-03-26T01:00:44.967+0000] {taskinstance.py:2698} ERROR - Task failed with exception
Traceback (most recent call last):
  File "/home/airflow/.local/lib/python3.8/site-packages/airflow/models/taskinstance.py", line 433, in _execute_task
    result = execute_callable(context=context, **execute_callable_kwargs)
  File "/home/airflow/.local/lib/python3.8/site-packages/airflow/operators/python.py", line 199, in execute
    return_value = self.execute_callable()
  File "/home/airflow/.local/lib/python3.8/site-packages/airflow/operators/python.py", line 216, in execute_callable
    return self.python_callable(*self.op_args, **self.op_kwargs)
  File "/opt/airflow/dags/pipeline.py", line 25, in prepare_data_task
    prepare_data(train_path, 'train')
  File "/opt/airflow/dags/func/ml_pipeline.py", line 54, in prepare_data
    if file_name == 'train.csv':
NameError: name 'file_name' is not defined
[2025-03-26T01:00:45.004+0000] {taskinstance.py:1138} INFO - Marking task as UP_FOR_RETRY. dag_id=titanic_survival_classifier, task_id=prepare_data_task, execution_date=20250326T010039, start_date=20250326T010044, end_date=20250326T010045
[2025-03-26T01:00:45.035+0000] {standard_task_runner.py:107} ERROR - Failed to execute job 23 for task prepare_data_task (name 'file_name' is not defined; 2159)
[2025-03-26T01:00:45.083+0000] {local_task_job_runner.py:234} INFO - Task exited with return code 1
[2025-03-26T01:00:45.127+0000] {taskinstance.py:3280} INFO - 0 downstream tasks scheduled from follow-on schedule check
