[2025-03-26T00:47:59.004+0000] {taskinstance.py:1956} INFO - Dependencies all met for dep_context=non-requeueable deps ti=<TaskInstance: titanic_survival_classifier.model_validation_task manual__2025-03-26T00:42:43.687439+00:00 [queued]>
[2025-03-26T00:47:59.020+0000] {taskinstance.py:1956} INFO - Dependencies all met for dep_context=requeueable deps ti=<TaskInstance: titanic_survival_classifier.model_validation_task manual__2025-03-26T00:42:43.687439+00:00 [queued]>
[2025-03-26T00:47:59.021+0000] {taskinstance.py:2170} INFO - Starting attempt 1 of 2
[2025-03-26T00:47:59.047+0000] {taskinstance.py:2191} INFO - Executing <Task(PythonOperator): model_validation_task> on 2025-03-26 00:42:43.687439+00:00
[2025-03-26T00:47:59.060+0000] {standard_task_runner.py:60} INFO - Started process 1648 to run task
[2025-03-26T00:47:59.065+0000] {standard_task_runner.py:87} INFO - Running: ['***', 'tasks', 'run', 'titanic_survival_classifier', 'model_validation_task', 'manual__2025-03-26T00:42:43.687439+00:00', '--job-id', '17', '--raw', '--subdir', 'DAGS_FOLDER/pipeline.py', '--cfg-path', '/tmp/tmpl69ydm91']
[2025-03-26T00:47:59.067+0000] {standard_task_runner.py:88} INFO - Job 17: Subtask model_validation_task
[2025-03-26T00:47:59.089+0000] {warnings.py:109} WARNING - /home/***/.local/lib/python3.8/site-packages/***/settings.py:194: DeprecationWarning: The sql_alchemy_conn option in [core] has been moved to the sql_alchemy_conn option in [database] - the old setting has been used, but please update your config.
  SQL_ALCHEMY_CONN = conf.get("database", "SQL_ALCHEMY_CONN")

[2025-03-26T00:47:59.152+0000] {task_command.py:423} INFO - Running <TaskInstance: titanic_survival_classifier.model_validation_task manual__2025-03-26T00:42:43.687439+00:00 [running]> on host 0f3b2e2ddf0a
[2025-03-26T00:47:59.294+0000] {taskinstance.py:2480} INFO - Exporting env vars: AIRFLOW_CTX_DAG_OWNER='***' AIRFLOW_CTX_DAG_ID='titanic_survival_classifier' AIRFLOW_CTX_TASK_ID='model_validation_task' AIRFLOW_CTX_EXECUTION_DATE='2025-03-26T00:42:43.687439+00:00' AIRFLOW_CTX_TRY_NUMBER='1' AIRFLOW_CTX_DAG_RUN_ID='manual__2025-03-26T00:42:43.687439+00:00'
[2025-03-26T00:47:59.327+0000] {logging_mixin.py:188} INFO - ---Testing Model---
[2025-03-26T00:47:59.344+0000] {logging_mixin.py:188} INFO - Test predictions complete
[2025-03-26T00:47:59.346+0000] {taskinstance.py:2698} ERROR - Task failed with exception
Traceback (most recent call last):
  File "/home/airflow/.local/lib/python3.8/site-packages/airflow/models/taskinstance.py", line 433, in _execute_task
    result = execute_callable(context=context, **execute_callable_kwargs)
  File "/home/airflow/.local/lib/python3.8/site-packages/airflow/operators/python.py", line 199, in execute
    return_value = self.execute_callable()
  File "/home/airflow/.local/lib/python3.8/site-packages/airflow/operators/python.py", line 216, in execute_callable
    return self.python_callable(*self.op_args, **self.op_kwargs)
  File "/opt/airflow/dags/pipeline.py", line 65, in model_validation_task
    if isinstance(result[1], pd.DataFrame):  # Unlabeled data
NameError: name 'pd' is not defined
[2025-03-26T00:47:59.364+0000] {taskinstance.py:1138} INFO - Marking task as UP_FOR_RETRY. dag_id=titanic_survival_classifier, task_id=model_validation_task, execution_date=20250326T004243, start_date=20250326T004759, end_date=20250326T004759
[2025-03-26T00:47:59.384+0000] {standard_task_runner.py:107} ERROR - Failed to execute job 17 for task model_validation_task (name 'pd' is not defined; 1648)
[2025-03-26T00:47:59.440+0000] {local_task_job_runner.py:234} INFO - Task exited with return code 1
[2025-03-26T00:47:59.479+0000] {taskinstance.py:3280} INFO - 0 downstream tasks scheduled from follow-on schedule check
